[2024-06-11T16:32:18.700+0000] {local_task_job_runner.py:120} INFO - ::group::Pre task execution logs
[2024-06-11T16:32:18.714+0000] {taskinstance.py:2076} INFO - Dependencies all met for dep_context=non-requeueable deps ti=<TaskInstance: stock_prediction.update_data manual__2024-06-11T16:32:11.459084+00:00 [queued]>
[2024-06-11T16:32:18.719+0000] {taskinstance.py:2076} INFO - Dependencies all met for dep_context=requeueable deps ti=<TaskInstance: stock_prediction.update_data manual__2024-06-11T16:32:11.459084+00:00 [queued]>
[2024-06-11T16:32:18.719+0000] {taskinstance.py:2306} INFO - Starting attempt 1 of 2
[2024-06-11T16:32:18.731+0000] {taskinstance.py:2330} INFO - Executing <Task(PythonOperator): update_data> on 2024-06-11 16:32:11.459084+00:00
[2024-06-11T16:32:18.737+0000] {warnings.py:112} WARNING - /home/***/.local/lib/python3.12/site-packages/***/task/task_runner/standard_task_runner.py:61: DeprecationWarning: This process (pid=431) is multi-threaded, use of fork() may lead to deadlocks in the child.
  pid = os.fork()

[2024-06-11T16:32:18.738+0000] {standard_task_runner.py:90} INFO - Running: ['***', 'tasks', 'run', 'stock_prediction', 'update_data', 'manual__2024-06-11T16:32:11.459084+00:00', '--job-id', '27', '--raw', '--subdir', 'DAGS_FOLDER/demo_***.py', '--cfg-path', '/tmp/tmp28u7uik2']
[2024-06-11T16:32:18.738+0000] {standard_task_runner.py:63} INFO - Started process 449 to run task
[2024-06-11T16:32:18.738+0000] {standard_task_runner.py:91} INFO - Job 27: Subtask update_data
[2024-06-11T16:32:18.771+0000] {task_command.py:426} INFO - Running <TaskInstance: stock_prediction.update_data manual__2024-06-11T16:32:11.459084+00:00 [running]> on host ad0cd89ef011
[2024-06-11T16:32:18.828+0000] {taskinstance.py:2648} INFO - Exporting env vars: AIRFLOW_CTX_DAG_OWNER='Nguyen Khoa Doan' AIRFLOW_CTX_DAG_ID='stock_prediction' AIRFLOW_CTX_TASK_ID='update_data' AIRFLOW_CTX_EXECUTION_DATE='2024-06-11T16:32:11.459084+00:00' AIRFLOW_CTX_TRY_NUMBER='1' AIRFLOW_CTX_DAG_RUN_ID='manual__2024-06-11T16:32:11.459084+00:00'
[2024-06-11T16:32:18.829+0000] {taskinstance.py:430} INFO - ::endgroup::
[2024-06-11T16:32:18.840+0000] {taskinstance.py:441} INFO - ::group::Post task execution logs
[2024-06-11T16:32:18.840+0000] {taskinstance.py:2905} ERROR - Task failed with exception
Traceback (most recent call last):
  File "/home/airflow/.local/lib/python3.12/site-packages/pandas/core/indexes/base.py", line 3791, in get_loc
    return self._engine.get_loc(casted_key)
           ^^^^^^^^^^^^^^^^^^^^^^^^^^^^^^^^
  File "index.pyx", line 152, in pandas._libs.index.IndexEngine.get_loc
  File "index.pyx", line 181, in pandas._libs.index.IndexEngine.get_loc
  File "pandas/_libs/hashtable_class_helper.pxi", line 7080, in pandas._libs.hashtable.PyObjectHashTable.get_item
  File "pandas/_libs/hashtable_class_helper.pxi", line 7088, in pandas._libs.hashtable.PyObjectHashTable.get_item
KeyError: 'date'

The above exception was the direct cause of the following exception:

Traceback (most recent call last):
  File "/home/airflow/.local/lib/python3.12/site-packages/airflow/models/taskinstance.py", line 465, in _execute_task
    result = _execute_callable(context=context, **execute_callable_kwargs)
             ^^^^^^^^^^^^^^^^^^^^^^^^^^^^^^^^^^^^^^^^^^^^^^^^^^^^^^^^^^^^^
  File "/home/airflow/.local/lib/python3.12/site-packages/airflow/models/taskinstance.py", line 432, in _execute_callable
    return execute_callable(context=context, **execute_callable_kwargs)
           ^^^^^^^^^^^^^^^^^^^^^^^^^^^^^^^^^^^^^^^^^^^^^^^^^^^^^^^^^^^^
  File "/home/airflow/.local/lib/python3.12/site-packages/airflow/models/baseoperator.py", line 401, in wrapper
    return func(self, *args, **kwargs)
           ^^^^^^^^^^^^^^^^^^^^^^^^^^^
  File "/home/airflow/.local/lib/python3.12/site-packages/airflow/operators/python.py", line 235, in execute
    return_value = self.execute_callable()
                   ^^^^^^^^^^^^^^^^^^^^^^^
  File "/home/airflow/.local/lib/python3.12/site-packages/airflow/operators/python.py", line 252, in execute_callable
    return self.python_callable(*self.op_args, **self.op_kwargs)
           ^^^^^^^^^^^^^^^^^^^^^^^^^^^^^^^^^^^^^^^^^^^^^^^^^^^^^
  File "/opt/airflow/dags/demo_airflow.py", line 43, in update_data
    start_date = existing_data['date'].max() if not existing_data.empty else '2014-01-01'
                 ~~~~~~~~~~~~~^^^^^^^^
  File "/home/airflow/.local/lib/python3.12/site-packages/pandas/core/frame.py", line 3893, in __getitem__
    indexer = self.columns.get_loc(key)
              ^^^^^^^^^^^^^^^^^^^^^^^^^
  File "/home/airflow/.local/lib/python3.12/site-packages/pandas/core/indexes/base.py", line 3798, in get_loc
    raise KeyError(key) from err
KeyError: 'date'
[2024-06-11T16:32:18.859+0000] {taskinstance.py:1206} INFO - Marking task as UP_FOR_RETRY. dag_id=stock_prediction, task_id=update_data, run_id=manual__2024-06-11T16:32:11.459084+00:00, execution_date=20240611T163211, start_date=20240611T163218, end_date=20240611T163218
[2024-06-11T16:32:18.870+0000] {standard_task_runner.py:110} ERROR - Failed to execute job 27 for task update_data ('date'; 449)
[2024-06-11T16:32:18.915+0000] {local_task_job_runner.py:240} INFO - Task exited with return code 1
[2024-06-11T16:32:18.945+0000] {taskinstance.py:3503} INFO - 0 downstream tasks scheduled from follow-on schedule check
[2024-06-11T16:32:18.950+0000] {local_task_job_runner.py:222} INFO - ::endgroup::
