[2024-06-12T14:33:55.789+0000] {local_task_job_runner.py:120} INFO - ::group::Pre task execution logs
[2024-06-12T14:33:55.808+0000] {taskinstance.py:2076} INFO - Dependencies all met for dep_context=non-requeueable deps ti=<TaskInstance: stock_prediction.training_task manual__2024-06-12T14:33:28.237310+00:00 [queued]>
[2024-06-12T14:33:55.816+0000] {taskinstance.py:2076} INFO - Dependencies all met for dep_context=requeueable deps ti=<TaskInstance: stock_prediction.training_task manual__2024-06-12T14:33:28.237310+00:00 [queued]>
[2024-06-12T14:33:55.817+0000] {taskinstance.py:2306} INFO - Starting attempt 1 of 2
[2024-06-12T14:33:55.832+0000] {taskinstance.py:2330} INFO - Executing <Task(PythonOperator): training_task> on 2024-06-12 14:33:28.237310+00:00
[2024-06-12T14:33:55.844+0000] {warnings.py:112} WARNING - /home/***/.local/lib/python3.12/site-packages/***/task/task_runner/standard_task_runner.py:61: DeprecationWarning: This process (pid=5102) is multi-threaded, use of fork() may lead to deadlocks in the child.
  pid = os.fork()

[2024-06-12T14:33:55.846+0000] {standard_task_runner.py:90} INFO - Running: ['***', 'tasks', 'run', 'stock_prediction', 'training_task', 'manual__2024-06-12T14:33:28.237310+00:00', '--job-id', '230', '--raw', '--subdir', 'DAGS_FOLDER/demo_***.py', '--cfg-path', '/tmp/tmp8fk0zvii']
[2024-06-12T14:33:55.846+0000] {standard_task_runner.py:63} INFO - Started process 5127 to run task
[2024-06-12T14:33:55.847+0000] {standard_task_runner.py:91} INFO - Job 230: Subtask training_task
[2024-06-12T14:33:55.889+0000] {task_command.py:426} INFO - Running <TaskInstance: stock_prediction.training_task manual__2024-06-12T14:33:28.237310+00:00 [running]> on host 33b4ab31339c
[2024-06-12T14:33:55.964+0000] {taskinstance.py:2648} INFO - Exporting env vars: AIRFLOW_CTX_DAG_OWNER='Nguyen Khoa Doan' AIRFLOW_CTX_DAG_ID='stock_prediction' AIRFLOW_CTX_TASK_ID='training_task' AIRFLOW_CTX_EXECUTION_DATE='2024-06-12T14:33:28.237310+00:00' AIRFLOW_CTX_TRY_NUMBER='1' AIRFLOW_CTX_DAG_RUN_ID='manual__2024-06-12T14:33:28.237310+00:00'
[2024-06-12T14:33:55.966+0000] {taskinstance.py:430} INFO - ::endgroup::
[2024-06-12T14:33:56.036+0000] {warnings.py:112} WARNING - /home/***/.local/lib/python3.12/site-packages/keras/src/layers/rnn/rnn.py:204: UserWarning: Do not pass an `input_shape`/`input_dim` argument to a layer. When using Sequential models, prefer using an `Input(shape)` object as the first layer in the model instead.
  super().__init__(**kwargs)

[2024-06-12T14:33:56.224+0000] {taskinstance.py:441} INFO - ::group::Post task execution logs
[2024-06-12T14:33:56.225+0000] {taskinstance.py:2905} ERROR - Task failed with exception
Traceback (most recent call last):
  File "/home/airflow/.local/lib/python3.12/site-packages/airflow/models/taskinstance.py", line 465, in _execute_task
    result = _execute_callable(context=context, **execute_callable_kwargs)
             ^^^^^^^^^^^^^^^^^^^^^^^^^^^^^^^^^^^^^^^^^^^^^^^^^^^^^^^^^^^^^
  File "/home/airflow/.local/lib/python3.12/site-packages/airflow/models/taskinstance.py", line 432, in _execute_callable
    return execute_callable(context=context, **execute_callable_kwargs)
           ^^^^^^^^^^^^^^^^^^^^^^^^^^^^^^^^^^^^^^^^^^^^^^^^^^^^^^^^^^^^
  File "/home/airflow/.local/lib/python3.12/site-packages/airflow/models/baseoperator.py", line 401, in wrapper
    return func(self, *args, **kwargs)
           ^^^^^^^^^^^^^^^^^^^^^^^^^^^
  File "/home/airflow/.local/lib/python3.12/site-packages/airflow/operators/python.py", line 235, in execute
    return_value = self.execute_callable()
                   ^^^^^^^^^^^^^^^^^^^^^^^
  File "/home/airflow/.local/lib/python3.12/site-packages/airflow/operators/python.py", line 252, in execute_callable
    return self.python_callable(*self.op_args, **self.op_kwargs)
           ^^^^^^^^^^^^^^^^^^^^^^^^^^^^^^^^^^^^^^^^^^^^^^^^^^^^^
  File "/opt/airflow/dags/demo_airflow.py", line 198, in training
    best_model = ModelCheckpoint(save_model, monitor='loss', verbose=2, save_best_only=True, mode='auto')
                 ^^^^^^^^^^^^^^^^^^^^^^^^^^^^^^^^^^^^^^^^^^^^^^^^^^^^^^^^^^^^^^^^^^^^^^^^^^^^^^^^^^^^^^^^
  File "/home/airflow/.local/lib/python3.12/site-packages/keras/src/callbacks/model_checkpoint.py", line 191, in __init__
    raise ValueError(
ValueError: The filepath provided must end in `.keras` (Keras model format). Received: filepath=/opt/***/data/model/save_model.hdf5
[2024-06-12T14:33:56.251+0000] {taskinstance.py:1206} INFO - Marking task as UP_FOR_RETRY. dag_id=stock_prediction, task_id=training_task, run_id=manual__2024-06-12T14:33:28.237310+00:00, execution_date=20240612T143328, start_date=20240612T143355, end_date=20240612T143356
[2024-06-12T14:33:56.262+0000] {standard_task_runner.py:110} ERROR - Failed to execute job 230 for task training_task (The filepath provided must end in `.keras` (Keras model format). Received: filepath=/opt/***/data/model/save_model.hdf5; 5127)
[2024-06-12T14:33:56.303+0000] {local_task_job_runner.py:240} INFO - Task exited with return code 1
[2024-06-12T14:33:56.320+0000] {taskinstance.py:3503} INFO - 0 downstream tasks scheduled from follow-on schedule check
[2024-06-12T14:33:56.323+0000] {local_task_job_runner.py:222} INFO - ::endgroup::
