[2024-06-13T10:40:21.709+0000] {local_task_job_runner.py:120} INFO - ::group::Pre task execution logs
[2024-06-13T10:40:21.726+0000] {taskinstance.py:2076} INFO - Dependencies all met for dep_context=non-requeueable deps ti=<TaskInstance: stock_prediction.test_model_task manual__2024-06-13T10:39:03.177714+00:00 [queued]>
[2024-06-13T10:40:21.732+0000] {taskinstance.py:2076} INFO - Dependencies all met for dep_context=requeueable deps ti=<TaskInstance: stock_prediction.test_model_task manual__2024-06-13T10:39:03.177714+00:00 [queued]>
[2024-06-13T10:40:21.732+0000] {taskinstance.py:2306} INFO - Starting attempt 1 of 2
[2024-06-13T10:40:21.742+0000] {taskinstance.py:2330} INFO - Executing <Task(PythonOperator): test_model_task> on 2024-06-13 10:39:03.177714+00:00
[2024-06-13T10:40:21.749+0000] {warnings.py:112} WARNING - /home/***/.local/lib/python3.12/site-packages/***/task/task_runner/standard_task_runner.py:61: DeprecationWarning: This process (pid=13041) is multi-threaded, use of fork() may lead to deadlocks in the child.
  pid = os.fork()

[2024-06-13T10:40:21.751+0000] {standard_task_runner.py:63} INFO - Started process 13059 to run task
[2024-06-13T10:40:21.750+0000] {standard_task_runner.py:90} INFO - Running: ['***', 'tasks', 'run', 'stock_prediction', 'test_model_task', 'manual__2024-06-13T10:39:03.177714+00:00', '--job-id', '444', '--raw', '--subdir', 'DAGS_FOLDER/demo_***.py', '--cfg-path', '/tmp/tmpslvgxihz']
[2024-06-13T10:40:21.751+0000] {standard_task_runner.py:91} INFO - Job 444: Subtask test_model_task
[2024-06-13T10:40:21.782+0000] {task_command.py:426} INFO - Running <TaskInstance: stock_prediction.test_model_task manual__2024-06-13T10:39:03.177714+00:00 [running]> on host 33b4ab31339c
[2024-06-13T10:40:21.841+0000] {taskinstance.py:2648} INFO - Exporting env vars: AIRFLOW_CTX_DAG_OWNER='Nguyen Khoa Doan' AIRFLOW_CTX_DAG_ID='stock_prediction' AIRFLOW_CTX_TASK_ID='test_model_task' AIRFLOW_CTX_EXECUTION_DATE='2024-06-13T10:39:03.177714+00:00' AIRFLOW_CTX_TRY_NUMBER='1' AIRFLOW_CTX_DAG_RUN_ID='manual__2024-06-13T10:39:03.177714+00:00'
[2024-06-13T10:40:21.842+0000] {taskinstance.py:430} INFO - ::endgroup::
[2024-06-13T10:40:22.160+0000] {taskinstance.py:441} INFO - ::group::Post task execution logs
[2024-06-13T10:40:22.160+0000] {taskinstance.py:2905} ERROR - Task failed with exception
Traceback (most recent call last):
  File "/home/airflow/.local/lib/python3.12/site-packages/airflow/models/taskinstance.py", line 465, in _execute_task
    result = _execute_callable(context=context, **execute_callable_kwargs)
             ^^^^^^^^^^^^^^^^^^^^^^^^^^^^^^^^^^^^^^^^^^^^^^^^^^^^^^^^^^^^^
  File "/home/airflow/.local/lib/python3.12/site-packages/airflow/models/taskinstance.py", line 432, in _execute_callable
    return execute_callable(context=context, **execute_callable_kwargs)
           ^^^^^^^^^^^^^^^^^^^^^^^^^^^^^^^^^^^^^^^^^^^^^^^^^^^^^^^^^^^^
  File "/home/airflow/.local/lib/python3.12/site-packages/airflow/models/baseoperator.py", line 401, in wrapper
    return func(self, *args, **kwargs)
           ^^^^^^^^^^^^^^^^^^^^^^^^^^^
  File "/home/airflow/.local/lib/python3.12/site-packages/airflow/operators/python.py", line 235, in execute
    return_value = self.execute_callable()
                   ^^^^^^^^^^^^^^^^^^^^^^^
  File "/home/airflow/.local/lib/python3.12/site-packages/airflow/operators/python.py", line 252, in execute_callable
    return self.python_callable(*self.op_args, **self.op_kwargs)
           ^^^^^^^^^^^^^^^^^^^^^^^^^^^^^^^^^^^^^^^^^^^^^^^^^^^^^
  File "/opt/airflow/dags/demo_airflow.py", line 268, in test_model
    sc_test = sc.transform(test)
              ^^^^^^^^^^^^^^^^^^
  File "/home/airflow/.local/lib/python3.12/site-packages/sklearn/utils/_set_output.py", line 313, in wrapped
    data_to_wrap = f(self, X, *args, **kwargs)
                   ^^^^^^^^^^^^^^^^^^^^^^^^^^^
  File "/home/airflow/.local/lib/python3.12/site-packages/sklearn/preprocessing/_data.py", line 530, in transform
    check_is_fitted(self)
  File "/home/airflow/.local/lib/python3.12/site-packages/sklearn/utils/validation.py", line 1632, in check_is_fitted
    raise NotFittedError(msg % {"name": type(estimator).__name__})
sklearn.exceptions.NotFittedError: This MinMaxScaler instance is not fitted yet. Call 'fit' with appropriate arguments before using this estimator.
[2024-06-13T10:40:22.170+0000] {taskinstance.py:1206} INFO - Marking task as UP_FOR_RETRY. dag_id=stock_prediction, task_id=test_model_task, run_id=manual__2024-06-13T10:39:03.177714+00:00, execution_date=20240613T103903, start_date=20240613T104021, end_date=20240613T104022
[2024-06-13T10:40:22.181+0000] {standard_task_runner.py:110} ERROR - Failed to execute job 444 for task test_model_task (This MinMaxScaler instance is not fitted yet. Call 'fit' with appropriate arguments before using this estimator.; 13059)
[2024-06-13T10:40:22.206+0000] {local_task_job_runner.py:240} INFO - Task exited with return code 1
[2024-06-13T10:40:22.225+0000] {taskinstance.py:3503} INFO - 0 downstream tasks scheduled from follow-on schedule check
[2024-06-13T10:40:22.228+0000] {local_task_job_runner.py:222} INFO - ::endgroup::
