[2024-06-13T14:10:57.488+0000] {local_task_job_runner.py:120} INFO - ::group::Pre task execution logs
[2024-06-13T14:10:57.503+0000] {taskinstance.py:2076} INFO - Dependencies all met for dep_context=non-requeueable deps ti=<TaskInstance: stock_prediction.test_model_task manual__2024-06-13T14:09:40.894199+00:00 [queued]>
[2024-06-13T14:10:57.508+0000] {taskinstance.py:2076} INFO - Dependencies all met for dep_context=requeueable deps ti=<TaskInstance: stock_prediction.test_model_task manual__2024-06-13T14:09:40.894199+00:00 [queued]>
[2024-06-13T14:10:57.508+0000] {taskinstance.py:2306} INFO - Starting attempt 1 of 2
[2024-06-13T14:10:57.518+0000] {taskinstance.py:2330} INFO - Executing <Task(PythonOperator): test_model_task> on 2024-06-13 14:09:40.894199+00:00
[2024-06-13T14:10:57.527+0000] {warnings.py:112} WARNING - /home/***/.local/lib/python3.12/site-packages/***/task/task_runner/standard_task_runner.py:61: DeprecationWarning: This process (pid=18839) is multi-threaded, use of fork() may lead to deadlocks in the child.
  pid = os.fork()

[2024-06-13T14:10:57.529+0000] {standard_task_runner.py:63} INFO - Started process 18864 to run task
[2024-06-13T14:10:57.528+0000] {standard_task_runner.py:90} INFO - Running: ['***', 'tasks', 'run', 'stock_prediction', 'test_model_task', 'manual__2024-06-13T14:09:40.894199+00:00', '--job-id', '470', '--raw', '--subdir', 'DAGS_FOLDER/demo_***.py', '--cfg-path', '/tmp/tmpamtq6b7e']
[2024-06-13T14:10:57.529+0000] {standard_task_runner.py:91} INFO - Job 470: Subtask test_model_task
[2024-06-13T14:10:57.557+0000] {task_command.py:426} INFO - Running <TaskInstance: stock_prediction.test_model_task manual__2024-06-13T14:09:40.894199+00:00 [running]> on host 33b4ab31339c
[2024-06-13T14:10:57.612+0000] {taskinstance.py:2648} INFO - Exporting env vars: AIRFLOW_CTX_DAG_OWNER='Nguyen Khoa Doan' AIRFLOW_CTX_DAG_ID='stock_prediction' AIRFLOW_CTX_TASK_ID='test_model_task' AIRFLOW_CTX_EXECUTION_DATE='2024-06-13T14:09:40.894199+00:00' AIRFLOW_CTX_TRY_NUMBER='1' AIRFLOW_CTX_DAG_RUN_ID='manual__2024-06-13T14:09:40.894199+00:00'
[2024-06-13T14:10:57.614+0000] {taskinstance.py:430} INFO - ::endgroup::
[2024-06-13T14:10:58.173+0000] {logging_mixin.py:188} INFO -  1/17 ━━━━━━━━━━━━━━━━━━━━ 3s 199ms/step
[2024-06-13T14:10:58.367+0000] {logging_mixin.py:188} INFO - 17/17 ━━━━━━━━━━━━━━━━━━━━ 0s 12ms/step 
[2024-06-13T14:10:58.368+0000] {logging_mixin.py:188} INFO - 17/17 ━━━━━━━━━━━━━━━━━━━━ 0s 12ms/step
[2024-06-13T14:10:58.383+0000] {logging_mixin.py:188} INFO - 521
[2024-06-13T14:10:58.403+0000] {warnings.py:112} WARNING - /opt/***/dags/demo_***.py:259: SettingWithCopyWarning: 
A value is trying to be set on a copy of a slice from a DataFrame.
Try using .loc[row_indexer,col_indexer] = value instead

See the caveats in the documentation: https://pandas.pydata.org/pandas-docs/stable/user_guide/indexing.html#returning-a-view-versus-a-copy
  test_data1['predict'] = y_test_predict  # thêm dữ liệu

[2024-06-13T14:10:58.407+0000] {logging_mixin.py:188} INFO - 2078
[2024-06-13T14:10:58.407+0000] {logging_mixin.py:188} INFO - 521
[2024-06-13T14:10:58.412+0000] {logging_mixin.py:188} INFO -               close
time               
2014-01-02  36390.0
2014-01-03  36660.0
2014-01-06  36660.0
2014-01-07  36390.0
2014-01-08  36660.0
...             ...
2024-06-07  67800.0
2024-06-10  67200.0
2024-06-11  66500.0
2024-06-12  67000.0
2024-06-13  66900.0

[2604 rows x 1 columns]
[2024-06-13T14:10:58.651+0000] {logging_mixin.py:188} INFO - Độ phù hợp tập test: 0.8897484713880903
[2024-06-13T14:10:58.652+0000] {logging_mixin.py:188} INFO - Sai số tuyệt đối trung bình trên tập test (VNĐ): 1024.5032839491362
[2024-06-13T14:10:58.653+0000] {logging_mixin.py:188} INFO - Phần trăm sai số tuyệt đối trung bình tập test: 0.014692943617809632
[2024-06-13T14:10:58.659+0000] {taskinstance.py:441} INFO - ::group::Post task execution logs
[2024-06-13T14:10:58.659+0000] {taskinstance.py:2905} ERROR - Task failed with exception
Traceback (most recent call last):
  File "/home/airflow/.local/lib/python3.12/site-packages/pandas/core/indexes/base.py", line 3791, in get_loc
    return self._engine.get_loc(casted_key)
           ^^^^^^^^^^^^^^^^^^^^^^^^^^^^^^^^
  File "index.pyx", line 152, in pandas._libs.index.IndexEngine.get_loc
  File "index.pyx", line 181, in pandas._libs.index.IndexEngine.get_loc
  File "pandas/_libs/hashtable_class_helper.pxi", line 7080, in pandas._libs.hashtable.PyObjectHashTable.get_item
  File "pandas/_libs/hashtable_class_helper.pxi", line 7088, in pandas._libs.hashtable.PyObjectHashTable.get_item
KeyError: 'time'

The above exception was the direct cause of the following exception:

Traceback (most recent call last):
  File "/home/airflow/.local/lib/python3.12/site-packages/airflow/models/taskinstance.py", line 465, in _execute_task
    result = _execute_callable(context=context, **execute_callable_kwargs)
             ^^^^^^^^^^^^^^^^^^^^^^^^^^^^^^^^^^^^^^^^^^^^^^^^^^^^^^^^^^^^^
  File "/home/airflow/.local/lib/python3.12/site-packages/airflow/models/taskinstance.py", line 432, in _execute_callable
    return execute_callable(context=context, **execute_callable_kwargs)
           ^^^^^^^^^^^^^^^^^^^^^^^^^^^^^^^^^^^^^^^^^^^^^^^^^^^^^^^^^^^^
  File "/home/airflow/.local/lib/python3.12/site-packages/airflow/models/baseoperator.py", line 401, in wrapper
    return func(self, *args, **kwargs)
           ^^^^^^^^^^^^^^^^^^^^^^^^^^^
  File "/home/airflow/.local/lib/python3.12/site-packages/airflow/operators/python.py", line 235, in execute
    return_value = self.execute_callable()
                   ^^^^^^^^^^^^^^^^^^^^^^^
  File "/home/airflow/.local/lib/python3.12/site-packages/airflow/operators/python.py", line 252, in execute_callable
    return self.python_callable(*self.op_args, **self.op_kwargs)
           ^^^^^^^^^^^^^^^^^^^^^^^^^^^^^^^^^^^^^^^^^^^^^^^^^^^^^
  File "/opt/airflow/dags/demo_airflow.py", line 291, in test_model
    next_date = df1['time'].iloc[-1] + pd.Timedelta(days=1)
                ~~~^^^^^^^^
  File "/home/airflow/.local/lib/python3.12/site-packages/pandas/core/frame.py", line 3893, in __getitem__
    indexer = self.columns.get_loc(key)
              ^^^^^^^^^^^^^^^^^^^^^^^^^
  File "/home/airflow/.local/lib/python3.12/site-packages/pandas/core/indexes/base.py", line 3798, in get_loc
    raise KeyError(key) from err
KeyError: 'time'
[2024-06-13T14:10:58.678+0000] {taskinstance.py:1206} INFO - Marking task as UP_FOR_RETRY. dag_id=stock_prediction, task_id=test_model_task, run_id=manual__2024-06-13T14:09:40.894199+00:00, execution_date=20240613T140940, start_date=20240613T141057, end_date=20240613T141058
[2024-06-13T14:10:58.692+0000] {standard_task_runner.py:110} ERROR - Failed to execute job 470 for task test_model_task ('time'; 18864)
[2024-06-13T14:10:58.712+0000] {local_task_job_runner.py:240} INFO - Task exited with return code 1
[2024-06-13T14:10:58.733+0000] {taskinstance.py:3503} INFO - 0 downstream tasks scheduled from follow-on schedule check
[2024-06-13T14:10:58.736+0000] {local_task_job_runner.py:222} INFO - ::endgroup::
